<?xml version="1.0" encoding="UTF-8"?>
<!-- Generated by org.testng.reporters.JUnitReportReporter -->
<testsuite hostname="LAPTOP-V86D6NKR" name="com.qa.tests.DemoTest" tests="4" failures="0" timestamp="18 Mar 2019 16:19:45 GMT" time="0.007" errors="1">
  <testcase name="add" time="0.000" classname="com.qa.tests.DemoTest"/>
  <testcase name="sub" time="0.007" classname="com.qa.tests.DemoTest"/>
  <testcase name="div" time="0.000" classname="com.qa.tests.DemoTest">
    <error type="junit.framework.AssertionFailedError" message="expected:&lt;30&gt; but was:&lt;2&gt;">
      <![CDATA[junit.framework.AssertionFailedError: expected:<30> but was:<2>
	at junit.framework.Assert.fail(Assert.java:50)
	at junit.framework.Assert.failNotEquals(Assert.java:287)
	at junit.framework.Assert.assertEquals(Assert.java:67)
	at junit.framework.Assert.assertEquals(Assert.java:199)
	at junit.framework.Assert.assertEquals(Assert.java:205)
	at com.qa.tests.DemoTest.div(DemoTest.java:30)
	at sun.reflect.NativeMethodAccessorImpl.invoke0(Native Method)
	at sun.reflect.NativeMethodAccessorImpl.invoke(Unknown Source)
	at sun.reflect.DelegatingMethodAccessorImpl.invoke(Unknown Source)
	at java.lang.reflect.Method.invoke(Unknown Source)
	at org.testng.internal.MethodInvocationHelper.invokeMethod(MethodInvocationHelper.java:80)
	at org.testng.internal.Invoker.invokeMethod(Invoker.java:714)
	at org.testng.internal.Invoker.invokeTestMethod(Invoker.java:901)
	at org.testng.internal.Invoker.invokeTestMethods(Invoker.java:1231)
	at org.testng.internal.TestMethodWorker.invokeTestMethods(TestMethodWorker.java:127)
	at org.testng.internal.TestMethodWorker.run(TestMethodWorker.java:111)
	at org.testng.TestRunner.privateRun(TestRunner.java:767)
	at org.testng.TestRunner.run(TestRunner.java:617)
	at org.testng.SuiteRunner.runTest(SuiteRunner.java:334)
	at org.testng.SuiteRunner.runSequentially(SuiteRunner.java:329)
	at org.testng.SuiteRunner.privateRun(SuiteRunner.java:291)
	at org.testng.SuiteRunner.run(SuiteRunner.java:240)
	at org.testng.SuiteRunnerWorker.runSuite(SuiteRunnerWorker.java:52)
	at org.testng.SuiteRunnerWorker.run(SuiteRunnerWorker.java:86)
	at org.testng.TestNG.runSuitesSequentially(TestNG.java:1198)
	at org.testng.TestNG.runSuitesLocally(TestNG.java:1123)
	at org.testng.TestNG.run(TestNG.java:1031)
	at org.testng.remote.AbstractRemoteTestNG.run(AbstractRemoteTestNG.java:115)
	at org.testng.remote.RemoteTestNG.initAndRun(RemoteTestNG.java:251)
	at org.testng.remote.RemoteTestNG.main(RemoteTestNG.java:77)
]]>
    </error>
  </testcase> <!-- div -->
  <testcase name="mul" time="0.000" classname="com.qa.tests.DemoTest"/>
</testsuite> <!-- com.qa.tests.DemoTest -->
